<?xml version='1.0' encoding='utf-8'?>
<robot name="husky_robot_UR3_mobile_manipulator">
  <material name="husky_Black">
    <color rgba="0.1 0.1 0.1 1.0" />
    </material>
  <material name="husky_Blue">
    <color rgba="0.0 0.0 0.8 1.0" />
    </material>
  <material name="husky_Green">
    <color rgba="0.0 0.8 0.0 1.0" />
    </material>
  <material name="husky_Grey">
    <color rgba="0.7 0.7 0.7 1.0" />
    </material>
  <material name="husky_DarkGrey">
    <color rgba="0.3 0.3 0.3 1.0" />
    </material>
  <material name="husky_Red">
    <color rgba="0.8 0.0 0.0 1.0" />
    </material>
  <material name="husky_White">
    <color rgba="1.0 1.0 1.0 1.0" />
    </material>
  <material name="husky_Yellow">
    <color rgba="0.8 0.8 0.0 1.0" />
    </material>
  <link name="husky_base_footprint" />
  <gazebo reference="husky_base_footprint">
    <material>Gazebo/DarkGrey</material>
    </gazebo>
  <joint name="husky_chassis_joint" type="fixed">
    <origin rpy="0 0 0" xyz="0 0 0.14493" />
    <parent link="husky_base_footprint" />
    <child link="husky_base_link" />
    </joint>
  <link name="husky_base_link">
    <visual>
      <origin rpy="0 0 0" xyz="0 0 0" />
      <geometry>
        <mesh filename="base_link.stl" />
        </geometry>
      <material name="husky_Black" />
      </visual>
    <collision>
      <origin rpy="0 0 0" xyz="0 0 0.12498" />
      <geometry>
        <box size="1.0074 0.5709 0.2675" />
        </geometry>
      </collision>
    <inertial>
      <mass value="33.455" />
      <origin xyz="-0.08748 -0.00085 0.09947" />
      <inertia ixx="0.6022" ixy="-0.02364" ixz="-0.1197" iyy="1.7386" iyz="-0.001544" izz="2.0296" />
      </inertial>
    </link>
  <gazebo reference="husky_base_link">
    </gazebo>
  <link name="husky_imu_link" />
  <joint name="husky_imu_joint" type="fixed">
    <origin rpy="$(optenv HUSKY_IMU_RPY 0 -1.5708 3.1416)" xyz="$(optenv HUSKY_IMU_XYZ 0.19 0 0.149)" />
    <parent link="husky_base_link" />
    <child link="husky_imu_link" />
    </joint>
  <gazebo reference="husky_imu_link">
    </gazebo>
  <link name="husky_front_left_wheel_link">
    <contact>
      <lateral_friction value="1.0" />
      <rolling_friction value="0.0" />
      <stiffness value="30000" />
      <damping value="1000" />
      </contact>
    <inertial>
      <mass value="2.637" />
      <origin xyz="0 0 0" />
      <inertia ixx="0.02467" ixy="0" ixz="0" iyy="0.02467" iyz="0" izz="0.04411" />
      </inertial>
    <visual>
      <origin rpy="0 0 0" xyz="0 0 0" />
      <geometry>
        <mesh filename="wheel.stl" />
        </geometry>
      <material name="husky_DarkGrey" />
      </visual>
    <collision>
      <origin rpy="1.570795 0 0" xyz="0 0 0" />
      <geometry>
        <cylinder length="0.1143" radius="0.17775" />
        </geometry>
      </collision>
    </link>
  <gazebo reference="husky_front_left_wheel_link">
    <mu1 value="1.0" />
    <mu2 value="1.0" />
    <kp value="10000000.0" />
    <kd value="1.0" />
    <fdir1 value="1 0 0" />
    <material>Gazebo/Grey</material>
    <turnGravityOff>false</turnGravityOff>
    </gazebo>
  <joint name="husky_front_left_wheel" type="continuous">
    <parent link="husky_base_link" />
    <child link="husky_front_left_wheel_link" />
    <origin rpy="0 0 0" xyz="0.256 0.2854 0.03282" />
    <axis rpy="0 0 0" xyz="0 1 0" />
    </joint>
  <transmission name="husky_front_left_wheel_trans" type="SimpleTransmission">
    <type>transmission_interface/SimpleTransmission</type>
    <actuator name="husky_front_left_wheel_motor">
      <mechanicalReduction>1</mechanicalReduction>
      </actuator>
    <joint name="husky_front_left_wheel">
      <hardwareInterface>VelocityJointInterface</hardwareInterface>
      </joint>
    </transmission>
  <link name="husky_front_right_wheel_link">
    <contact>
      <lateral_friction value="1.0" />
      <rolling_friction value="0.0" />
      <stiffness value="30000" />
      <damping value="1000" />
      </contact>
    <inertial>
      <mass value="2.637" />
      <origin xyz="0 0 0" />
      <inertia ixx="0.02467" ixy="0" ixz="0" iyy="0.02467" iyz="0" izz="0.04411" />
      </inertial>
    <visual>
      <origin rpy="0 0 0" xyz="0 0 0" />
      <geometry>
        <mesh filename="wheel.stl" />
        </geometry>
      <material name="husky_DarkGrey" />
      </visual>
    <collision>
      <origin rpy="1.570795 0 0" xyz="0 0 0" />
      <geometry>
        <cylinder length="0.1143" radius="0.17775" />
        </geometry>
      </collision>
    </link>
  <gazebo reference="husky_front_right_wheel_link">
    <mu1 value="1.0" />
    <mu2 value="1.0" />
    <kp value="10000000.0" />
    <kd value="1.0" />
    <fdir1 value="1 0 0" />
    <material>Gazebo/Grey</material>
    <turnGravityOff>false</turnGravityOff>
    </gazebo>
  <joint name="husky_front_right_wheel" type="continuous">
    <parent link="husky_base_link" />
    <child link="husky_front_right_wheel_link" />
    <origin rpy="0 0 0" xyz="0.256 -0.2854 0.03282" />
    <axis rpy="0 0 0" xyz="0 1 0" />
    </joint>
  <transmission name="husky_front_right_wheel_trans" type="SimpleTransmission">
    <type>transmission_interface/SimpleTransmission</type>
    <actuator name="husky_front_right_wheel_motor">
      <mechanicalReduction>1</mechanicalReduction>
      </actuator>
    <joint name="husky_front_right_wheel">
      <hardwareInterface>VelocityJointInterface</hardwareInterface>
      </joint>
    </transmission>
  <link name="husky_rear_left_wheel_link">
    <contact>
      <lateral_friction value="1.0" />
      <rolling_friction value="0.0" />
      <stiffness value="30000" />
      <damping value="1000" />
      </contact>
    <inertial>
      <mass value="2.637" />
      <origin xyz="0 0 0" />
      <inertia ixx="0.02467" ixy="0" ixz="0" iyy="0.02467" iyz="0" izz="0.04411" />
      </inertial>
    <visual>
      <origin rpy="0 0 0" xyz="0 0 0" />
      <geometry>
        <mesh filename="wheel.stl" />
        </geometry>
      <material name="husky_DarkGrey" />
      </visual>
    <collision>
      <origin rpy="1.570795 0 0" xyz="0 0 0" />
      <geometry>
        <cylinder length="0.1143" radius="0.17775" />
        </geometry>
      </collision>
    </link>
  <gazebo reference="husky_rear_left_wheel_link">
    <mu1 value="1.0" />
    <mu2 value="1.0" />
    <kp value="10000000.0" />
    <kd value="1.0" />
    <fdir1 value="1 0 0" />
    <material>Gazebo/Grey</material>
    <turnGravityOff>false</turnGravityOff>
    </gazebo>
  <joint name="husky_rear_left_wheel" type="continuous">
    <parent link="husky_base_link" />
    <child link="husky_rear_left_wheel_link" />
    <origin rpy="0 0 0" xyz="-0.256 0.2854 0.03282" />
    <axis rpy="0 0 0" xyz="0 1 0" />
    </joint>
  <transmission name="husky_rear_left_wheel_trans" type="SimpleTransmission">
    <type>transmission_interface/SimpleTransmission</type>
    <actuator name="husky_rear_left_wheel_motor">
      <mechanicalReduction>1</mechanicalReduction>
      </actuator>
    <joint name="husky_rear_left_wheel">
      <hardwareInterface>VelocityJointInterface</hardwareInterface>
      </joint>
    </transmission>
  <link name="husky_rear_right_wheel_link">
    <contact>
      <lateral_friction value="1.0" />
      <rolling_friction value="0.0" />
      <stiffness value="30000" />
      <damping value="1000" />
      </contact>
    <inertial>
      <mass value="2.637" />
      <origin xyz="0 0 0" />
      <inertia ixx="0.02467" ixy="0" ixz="0" iyy="0.02467" iyz="0" izz="0.04411" />
      </inertial>
    <visual>
      <origin rpy="0 0 0" xyz="0 0 0" />
      <geometry>
        <mesh filename="wheel.stl" />
        </geometry>
      <material name="husky_DarkGrey" />
      </visual>
    <collision>
      <origin rpy="1.570795 0 0" xyz="0 0 0" />
      <geometry>
        <cylinder length="0.1143" radius="0.17775" />
        </geometry>
      </collision>
    </link>
  <gazebo reference="husky_rear_right_wheel_link">
    <mu1 value="1.0" />
    <mu2 value="1.0" />
    <kp value="10000000.0" />
    <kd value="1.0" />
    <fdir1 value="1 0 0" />
    <material>Gazebo/Grey</material>
    <turnGravityOff>false</turnGravityOff>
    </gazebo>
  <joint name="husky_rear_right_wheel" type="continuous">
    <parent link="husky_base_link" />
    <child link="husky_rear_right_wheel_link" />
    <origin rpy="0 0 0" xyz="-0.256 -0.2854 0.03282" />
    <axis rpy="0 0 0" xyz="0 1 0" />
    </joint>
  <transmission name="husky_rear_right_wheel_trans" type="SimpleTransmission">
    <type>transmission_interface/SimpleTransmission</type>
    <actuator name="husky_rear_right_wheel_motor">
      <mechanicalReduction>1</mechanicalReduction>
      </actuator>
    <joint name="husky_rear_right_wheel">
      <hardwareInterface>VelocityJointInterface</hardwareInterface>
      </joint>
    </transmission>
  <link name="husky_top_plate_link">
    <visual>
      <origin rpy="0 0 0" xyz="0 0 0" />
      <geometry>
        <mesh filename="top_plate.stl" />
        </geometry>
      <material name="husky_Yellow" />
      </visual>
    </link>
  <joint name="husky_top_plate" type="fixed">
    <parent link="husky_base_link" />
    <child link="husky_top_plate_link" />
    </joint>
  <gazebo reference="husky_top_plate_link">
    <material>Gazebo/Yellow</material>
    </gazebo>
  <link name="husky_user_rail_link">
    <visual>
      <geometry>
        <mesh filename="user_rail.stl" />
        </geometry>
      <material name="husky_DarkGrey" />
      </visual>
    </link>
  <joint name="husky_user_rail" type="fixed">
    <origin rpy="0 0 0" xyz="0.272 0 0.245" />
    <parent link="husky_base_link" />
    <child link="husky_user_rail_link" />
    </joint>
  <gazebo reference="husky_user_rail_link">
    <material>Gazebo/DarkGrey</material>
    </gazebo>
  <link name="husky_front_bumper_link">
    <visual>
      <geometry>
        <mesh filename="bumper.stl" />
        </geometry>
      <material name="husky_DarkGrey" />
      </visual>
    </link>
  <joint name="husky_front_bumper" type="fixed">
    <origin rpy="0 0 0" xyz="0.48 0 0.091" />
    <parent link="husky_base_link" />
    <child link="husky_front_bumper_link" />
    </joint>
  <gazebo reference="husky_front_bumper_link">
    <material>Gazebo/DarkGrey</material>
    </gazebo>
  <link name="husky_rear_bumper_link">
    <visual>
      <geometry>
        <mesh filename="bumper.stl" />
        </geometry>
      <material name="husky_DarkGrey" />
      </visual>
    </link>
  <joint name="husky_rear_bumper" type="fixed">
    <origin rpy="0 0 3.14159" xyz="-0.48 0 0.091" />
    <parent link="husky_base_link" />
    <child link="husky_rear_bumper_link" />
    </joint>
  <gazebo reference="husky_rear_bumper_link">
    <material>Gazebo/DarkGrey</material>
    </gazebo>
  <link name="ur3_robot_base">
    <collision name="ur3_UR3">
      <origin rpy="-3.141593 3.141593 -3.141593" xyz="0.000000 0.000000 0.043026" />
      <geometry>
        <mesh filename="UR3_robot_base_coll_1.dae" />
        </geometry>
      </collision>
    <visual name="ur3_link1_visible">
      <origin rpy="-3.141593 3.141593 -3.141593" xyz="0.000125 0.000086 0.043025" />
      <geometry>
        <mesh filename="UR3_link1_visible_vis_1.dae" />
        </geometry>
      <material name="ur3_link1_visible_material">
        <color rgba="0.870588 0.870588 0.870588 1.0" />
        </material>
      </visual>
    <visual name="ur3_link1_visible">
      <origin rpy="-3.141593 3.141593 -3.141593" xyz="0.000125 0.000086 0.043025" />
      <geometry>
        <mesh filename="UR3_link1_visible_vis_2.dae" />
        </geometry>
      <material name="ur3_link1_visible_material">
        <color rgba="0.282353 0.282353 0.282353 1.0" />
        </material>
      </visual>
    </link>
  <joint type="revolute" name="ur3_joint">
    <axis xyz="0 0 1" />
    <limit upper="6.2831854820251" lower="-6.2831854820251" velocity="3.1415927410126" effort="50.0" />
    <parent link="ur3_robot_base" />
    <child link="ur3_link" />
    <origin rpy="-3.141593 3.141593 -1.570796" xyz="0.000125 0.000086 0.147498" />
    </joint>
  <link name="ur3_link">
    <inertial>
      <origin rpy="-3.141593 3.141593 1.570796" xyz="-0.000082 0.006868 -0.001827" />
      <inertia izz="0.0099350964551032" iyz="1.1680027939965e-06" ixx="0.013322851015861" iyy="0.01409502211253" ixy="2.844135051548e-09" ixz="0.00033951027518348" />
      <mass value="1.0" />
      </inertial>
    <collision name="ur3_link">
      <origin rpy="-3.141593 3.141593 1.570796" xyz="-0.000156 0.003743 -0.000453" />
      <geometry>
        <mesh filename="UR3_link_coll_1.dae" />
        </geometry>
      </collision>
    <visual name="ur3_link2_visible">
      <origin rpy="-3.141593 3.141593 1.570796" xyz="-0.000156 0.003742 -0.000099" />
      <geometry>
        <mesh filename="UR3_link2_visible_vis_1.dae" />
        </geometry>
      <material name="ur3_link2_visible_material">
        <color rgba="0.535294 0.535294 0.535294 1.0" />
        </material>
      </visual>
    <visual name="ur3_link2_visible">
      <origin rpy="-3.141593 3.141593 1.570796" xyz="-0.000156 0.003742 -0.000099" />
      <geometry>
        <mesh filename="UR3_link2_visible_vis_2.dae" />
        </geometry>
      <material name="ur3_link2_visible_material">
        <color rgba="0.508235 0.761224 0.903529 1.0" />
        </material>
      </visual>
    <visual name="ur3_link2_visible">
      <origin rpy="-3.141593 3.141593 1.570796" xyz="-0.000156 0.003742 -0.000099" />
      <geometry>
        <mesh filename="UR3_link2_visible_vis_3.dae" />
        </geometry>
      <material name="ur3_link2_visible_material">
        <color rgba="0.535294 0.535294 0.535294 1.0" />
        </material>
      </visual>
    <visual name="ur3_link2_visible">
      <origin rpy="-3.141593 3.141593 1.570796" xyz="-0.000156 0.003742 -0.000099" />
      <geometry>
        <mesh filename="UR3_link2_visible_vis_4.dae" />
        </geometry>
      <material name="ur3_link2_visible_material">
        <color rgba="0.282353 0.282353 0.282353 1.0" />
        </material>
      </visual>
    </link>
  <joint type="revolute" name="ur3_joint_2">
    <axis xyz="0 0 1" />
    <limit upper="6.2831854820251" lower="-6.2831854820251" velocity="3.1415927410126" effort="50.0" />
    <parent link="ur3_link" />
    <child link="ur3_link_2" />
    <origin rpy="1.570795 3.141593 -3.141593" xyz="-0.000031 0.111666 0.004400" />
    </joint>
  <link name="ur3_link_2">
    <inertial>
      <origin rpy="1.570796 1.570796 0.000000" xyz="0.000069 -0.108116 0.006647" />
      <inertia izz="0.03454149621641" iyz="4.695736461373e-05" ixx="0.17734117337558" iyy="0.18813148649674" ixy="1.4690480381395e-05" ixz="0.0079891854119392" />
      <mass value="2.5" />
      </inertial>
    <collision name="ur3_link">
      <origin rpy="1.570796 1.570796 0.000000" xyz="0.000156 -0.117791 0.003851" />
      <geometry>
        <mesh filename="UR3_link_2_coll_1.dae" />
        </geometry>
      </collision>
    <collision name="ur3_link">
      <origin rpy="1.570796 1.570796 0.000000" xyz="0.000156 -0.117791 0.003851" />
      <geometry>
        <mesh filename="UR3_link_2_coll_2.dae" />
        </geometry>
      </collision>
    <collision name="ur3_link">
      <origin rpy="1.570796 1.570796 0.000000" xyz="0.000156 -0.117791 0.003851" />
      <geometry>
        <mesh filename="UR3_link_2_coll_3.dae" />
        </geometry>
      </collision>
    <collision name="ur3_link">
      <origin rpy="1.570796 1.570796 0.000000" xyz="0.000156 -0.117791 0.003851" />
      <geometry>
        <mesh filename="UR3_link_2_coll_4.dae" />
        </geometry>
      </collision>
    <collision name="ur3_link">
      <origin rpy="1.570796 1.570796 0.000000" xyz="0.000156 -0.117791 0.003851" />
      <geometry>
        <mesh filename="UR3_link_2_coll_5.dae" />
        </geometry>
      </collision>
    <visual name="ur3_link3_visible">
      <origin rpy="1.570796 1.570796 0.000000" xyz="0.000156 -0.117937 0.003778" />
      <geometry>
        <mesh filename="UR3_link3_visible_vis_1.dae" />
        </geometry>
      <material name="ur3_link3_visible_material">
        <color rgba="0.870588 0.870588 0.870588 1.0" />
        </material>
      </visual>
    <visual name="ur3_link3_visible">
      <origin rpy="1.570796 1.570796 0.000000" xyz="0.000156 -0.117937 0.003778" />
      <geometry>
        <mesh filename="UR3_link3_visible_vis_2.dae" />
        </geometry>
      <material name="ur3_link3_visible_material">
        <color rgba="0.282353 0.282353 0.282353 1.0" />
        </material>
      </visual>
    <visual name="ur3_link3_visible">
      <origin rpy="1.570796 1.570796 0.000000" xyz="0.000156 -0.117937 0.003778" />
      <geometry>
        <mesh filename="UR3_link3_visible_vis_3.dae" />
        </geometry>
      <material name="ur3_link3_visible_material">
        <color rgba="0.282353 0.282353 0.282353 1.0" />
        </material>
      </visual>
    <visual name="ur3_link3_visible">
      <origin rpy="1.570796 1.570796 0.000000" xyz="0.000156 -0.117937 0.003778" />
      <geometry>
        <mesh filename="UR3_link3_visible_vis_4.dae" />
        </geometry>
      <material name="ur3_link3_visible_material">
        <color rgba="0.535294 0.535294 0.535294 1.0" />
        </material>
      </visual>
    <visual name="ur3_link3_visible">
      <origin rpy="1.570796 1.570796 0.000000" xyz="0.000156 -0.117937 0.003778" />
      <geometry>
        <mesh filename="UR3_link3_visible_vis_5.dae" />
        </geometry>
      <material name="ur3_link3_visible_material">
        <color rgba="0.282353 0.282353 0.282353 1.0" />
        </material>
      </visual>
    <visual name="ur3_link3_visible">
      <origin rpy="1.570796 1.570796 0.000000" xyz="0.000156 -0.117937 0.003778" />
      <geometry>
        <mesh filename="UR3_link3_visible_vis_6.dae" />
        </geometry>
      <material name="ur3_link3_visible_material">
        <color rgba="0.535294 0.535294 0.535294 1.0" />
        </material>
      </visual>
    <visual name="ur3_link3_visible">
      <origin rpy="1.570796 1.570796 0.000000" xyz="0.000156 -0.117937 0.003778" />
      <geometry>
        <mesh filename="UR3_link3_visible_vis_7.dae" />
        </geometry>
      <material name="ur3_link3_visible_material">
        <color rgba="0.508235 0.761224 0.903529 1.0" />
        </material>
      </visual>
    <visual name="ur3_link3_visible">
      <origin rpy="1.570796 1.570796 0.000000" xyz="0.000156 -0.117937 0.003778" />
      <geometry>
        <mesh filename="UR3_link3_visible_vis_8.dae" />
        </geometry>
      <material name="ur3_link3_visible_material">
        <color rgba="0.535294 0.535294 0.535294 1.0" />
        </material>
      </visual>
    <visual name="ur3_link3_visible">
      <origin rpy="1.570796 1.570796 0.000000" xyz="0.000156 -0.117937 0.003778" />
      <geometry>
        <mesh filename="UR3_link3_visible_vis_9.dae" />
        </geometry>
      <material name="ur3_link3_visible_material">
        <color rgba="0.535294 0.535294 0.535294 1.0" />
        </material>
      </visual>
    <visual name="ur3_link3_visible">
      <origin rpy="1.570796 1.570796 0.000000" xyz="0.000156 -0.117937 0.003778" />
      <geometry>
        <mesh filename="UR3_link3_visible_vis_10.dae" />
        </geometry>
      <material name="ur3_link3_visible_material">
        <color rgba="0.508235 0.761224 0.903529 1.0" />
        </material>
      </visual>
    </link>
  <joint type="revolute" name="ur3_joint_3">
    <axis xyz="0 0 1" />
    <limit upper="6.2831854820251" lower="-6.2831854820251" velocity="3.1415927410126" effort="50.0" />
    <parent link="ur3_link_2" />
    <child link="ur3_link_3" />
    <origin rpy="-3.141593 3.141593 -3.141593" xyz="0.000076 -0.243650 -0.000000" />
    </joint>
  <link name="ur3_link_3">
    <inertial>
      <origin rpy="1.570796 1.570796 0.000000" xyz="-0.000100 -0.117175 -0.077228" />
      <inertia izz="0.019407330650231" iyz="-2.1974749022959e-05" ixx="0.12383162690089" iyy="0.12850853130719" ixy="-2.2961357759829e-05" ixz="-0.0073093291977017" />
      <mass value="2.5" />
      </inertial>
    <collision name="ur3_link">
      <origin rpy="1.570796 1.570796 0.000000" xyz="-0.000163 -0.103964 -0.083482" />
      <geometry>
        <mesh filename="UR3_link_3_coll_1.dae" />
        </geometry>
      </collision>
    <collision name="ur3_link">
      <origin rpy="1.570796 1.570796 0.000000" xyz="-0.000163 -0.103964 -0.083482" />
      <geometry>
        <mesh filename="UR3_link_3_coll_2.dae" />
        </geometry>
      </collision>
    <collision name="ur3_link">
      <origin rpy="1.570796 1.570796 0.000000" xyz="-0.000163 -0.103964 -0.083482" />
      <geometry>
        <mesh filename="UR3_link_3_coll_3.dae" />
        </geometry>
      </collision>
    <collision name="ur3_link">
      <origin rpy="1.570796 1.570796 0.000000" xyz="-0.000163 -0.103964 -0.083482" />
      <geometry>
        <mesh filename="UR3_link_3_coll_4.dae" />
        </geometry>
      </collision>
    <collision name="ur3_link">
      <origin rpy="1.570796 1.570796 0.000000" xyz="-0.000163 -0.103964 -0.083482" />
      <geometry>
        <mesh filename="UR3_link_3_coll_5.dae" />
        </geometry>
      </collision>
    <visual name="ur3_link4_visible">
      <origin rpy="1.570796 1.570796 0.000000" xyz="-0.000026 -0.103830 -0.082434" />
      <geometry>
        <mesh filename="UR3_link4_visible_vis_1.dae" />
        </geometry>
      <material name="ur3_link4_visible_material">
        <color rgba="0.870588 0.870588 0.870588 1.0" />
        </material>
      </visual>
    <visual name="ur3_link4_visible">
      <origin rpy="1.570796 1.570796 0.000000" xyz="-0.000026 -0.103830 -0.082434" />
      <geometry>
        <mesh filename="UR3_link4_visible_vis_2.dae" />
        </geometry>
      <material name="ur3_link4_visible_material">
        <color rgba="0.282353 0.282353 0.282353 1.0" />
        </material>
      </visual>
    <visual name="ur3_link4_visible">
      <origin rpy="1.570796 1.570796 0.000000" xyz="-0.000026 -0.103830 -0.082434" />
      <geometry>
        <mesh filename="UR3_link4_visible_vis_3.dae" />
        </geometry>
      <material name="ur3_link4_visible_material">
        <color rgba="0.282353 0.282353 0.282353 1.0" />
        </material>
      </visual>
    <visual name="ur3_link4_visible">
      <origin rpy="1.570796 1.570796 0.000000" xyz="-0.000026 -0.103830 -0.082434" />
      <geometry>
        <mesh filename="UR3_link4_visible_vis_4.dae" />
        </geometry>
      <material name="ur3_link4_visible_material">
        <color rgba="0.535294 0.535294 0.535294 1.0" />
        </material>
      </visual>
    <visual name="ur3_link4_visible">
      <origin rpy="1.570796 1.570796 0.000000" xyz="-0.000026 -0.103830 -0.082434" />
      <geometry>
        <mesh filename="UR3_link4_visible_vis_5.dae" />
        </geometry>
      <material name="ur3_link4_visible_material">
        <color rgba="0.282353 0.282353 0.282353 1.0" />
        </material>
      </visual>
    <visual name="ur3_link4_visible">
      <origin rpy="1.570796 1.570796 0.000000" xyz="-0.000026 -0.103830 -0.082434" />
      <geometry>
        <mesh filename="UR3_link4_visible_vis_6.dae" />
        </geometry>
      <material name="ur3_link4_visible_material">
        <color rgba="0.508235 0.761224 0.903529 1.0" />
        </material>
      </visual>
    <visual name="ur3_link4_visible">
      <origin rpy="1.570796 1.570796 0.000000" xyz="-0.000026 -0.103830 -0.082434" />
      <geometry>
        <mesh filename="UR3_link4_visible_vis_7.dae" />
        </geometry>
      <material name="ur3_link4_visible_material">
        <color rgba="0.535294 0.535294 0.535294 1.0" />
        </material>
      </visual>
    <visual name="ur3_link4_visible">
      <origin rpy="1.570796 1.570796 0.000000" xyz="-0.000026 -0.103830 -0.082434" />
      <geometry>
        <mesh filename="UR3_link4_visible_vis_8.dae" />
        </geometry>
      <material name="ur3_link4_visible_material">
        <color rgba="0.535294 0.535294 0.535294 1.0" />
        </material>
      </visual>
    <visual name="ur3_link4_visible">
      <origin rpy="1.570796 1.570796 0.000000" xyz="-0.000026 -0.103830 -0.082434" />
      <geometry>
        <mesh filename="UR3_link4_visible_vis_9.dae" />
        </geometry>
      <material name="ur3_link4_visible_material">
        <color rgba="0.282353 0.282353 0.282353 1.0" />
        </material>
      </visual>
    </link>
  <joint type="revolute" name="ur3_joint_4">
    <axis xyz="0 0 1" />
    <limit upper="6.2831854820251" lower="-6.2831854820251" velocity="6.2831854820251" effort="50.0" />
    <parent link="ur3_link_3" />
    <child link="ur3_link_4" />
    <origin rpy="-3.141591 3.141593 -3.141593" xyz="-0.000045 -0.213250 -0.000001" />
    </joint>
  <link name="ur3_link_4">
    <inertial>
      <origin rpy="1.570796 1.570796 0.000000" xyz="-0.000063 -0.002676 -0.002551" />
      <inertia izz="0.0046337627007229" iyz="1.9329876560889e-05" ixx="0.0074607414118797" iyy="0.0076237864851809" ixy="-1.3022311240541e-06" ixz="4.4444737658457e-05" />
      <mass value="1.0" />
      </inertial>
    <collision name="ur3_link">
      <origin rpy="1.570796 1.570796 0.000000" xyz="0.000054 -0.001230 -0.000576" />
      <geometry>
        <mesh filename="UR3_link_4_coll_1.dae" />
        </geometry>
      </collision>
    <visual name="ur3_link5_visible">
      <origin rpy="1.570796 1.570796 0.000000" xyz="0.000055 -0.001035 -0.001538" />
      <geometry>
        <mesh filename="UR3_link5_visible_vis_1.dae" />
        </geometry>
      <material name="ur3_link5_visible_material">
        <color rgba="0.535294 0.535294 0.535294 1.0" />
        </material>
      </visual>
    <visual name="ur3_link5_visible">
      <origin rpy="1.570796 1.570796 0.000000" xyz="0.000055 -0.001035 -0.001538" />
      <geometry>
        <mesh filename="UR3_link5_visible_vis_2.dae" />
        </geometry>
      <material name="ur3_link5_visible_material">
        <color rgba="0.535294 0.535294 0.535294 1.0" />
        </material>
      </visual>
    <visual name="ur3_link5_visible">
      <origin rpy="1.570796 1.570796 0.000000" xyz="0.000055 -0.001035 -0.001538" />
      <geometry>
        <mesh filename="UR3_link5_visible_vis_3.dae" />
        </geometry>
      <material name="ur3_link5_visible_material">
        <color rgba="0.508235 0.761224 0.903529 1.0" />
        </material>
      </visual>
    <visual name="ur3_link5_visible">
      <origin rpy="1.570796 1.570796 0.000000" xyz="0.000055 -0.001035 -0.001538" />
      <geometry>
        <mesh filename="UR3_link5_visible_vis_4.dae" />
        </geometry>
      <material name="ur3_link5_visible_material">
        <color rgba="0.282353 0.282353 0.282353 1.0" />
        </material>
      </visual>
    </link>
  <joint type="revolute" name="ur3_joint_5">
    <axis xyz="0 0 1" />
    <limit upper="6.2831854820251" lower="-6.2831854820251" velocity="6.2831854820251" effort="50.0" />
    <parent link="ur3_link_4" />
    <child link="ur3_link_5" />
    <origin rpy="-1.570796 3.141593 -3.141593" xyz="-0.000000 -0.084218 0.000684" />
    </joint>
  <link name="ur3_link_5">
    <inertial>
      <origin rpy="-3.141593 3.141593 1.570796" xyz="0.000520 0.003355 -0.001879" />
      <inertia izz="0.0076031188661991" iyz="-2.5701652848516e-06" ixx="0.0046708090457454" iyy="0.0077851674584931" ixy="1.0248622227352e-05" ixz="7.4333852122585e-05" />
      <mass value="1.0" />
      </inertial>
    <collision name="ur3_link">
      <origin rpy="-3.141593 3.141593 1.570796" xyz="0.000419 0.001893 -0.000068" />
      <geometry>
        <mesh filename="UR3_link_5_coll_1.dae" />
        </geometry>
      </collision>
    <visual name="ur3_link6_visible">
      <origin rpy="-3.141593 3.141593 1.570796" xyz="0.000353 0.001806 -0.001000" />
      <geometry>
        <mesh filename="UR3_link6_visible_vis_1.dae" />
        </geometry>
      <material name="ur3_link6_visible_material">
        <color rgba="0.535294 0.535294 0.535294 1.0" />
        </material>
      </visual>
    <visual name="ur3_link6_visible">
      <origin rpy="-3.141593 3.141593 1.570796" xyz="0.000353 0.001806 -0.001000" />
      <geometry>
        <mesh filename="UR3_link6_visible_vis_2.dae" />
        </geometry>
      <material name="ur3_link6_visible_material">
        <color rgba="0.535294 0.535294 0.535294 1.0" />
        </material>
      </visual>
    <visual name="ur3_link6_visible">
      <origin rpy="-3.141593 3.141593 1.570796" xyz="0.000353 0.001806 -0.001000" />
      <geometry>
        <mesh filename="UR3_link6_visible_vis_3.dae" />
        </geometry>
      <material name="ur3_link6_visible_material">
        <color rgba="0.508235 0.761224 0.903529 1.0" />
        </material>
      </visual>
    <visual name="ur3_link6_visible">
      <origin rpy="-3.141593 3.141593 1.570796" xyz="0.000353 0.001806 -0.001000" />
      <geometry>
        <mesh filename="UR3_link6_visible_vis_4.dae" />
        </geometry>
      <material name="ur3_link6_visible_material">
        <color rgba="0.282353 0.282353 0.282353 1.0" />
        </material>
      </visual>
    </link>
  <joint type="continuous" name="ur3_joint_6">
    <axis xyz="0 0 1" />
    <parent link="ur3_link_5" />
    <child link="ur3_link_6" />
    <origin rpy="1.570796 3.141593 -3.141593" xyz="-0.000000 -0.000684 0.001132" />
    </joint>
  <link name="ur3_link_6">
    <inertial>
      <origin rpy="-0.000000 3.141593 -3.141593" xyz="0.000095 -0.000194 0.066355" />
      <inertia izz="0.0038747105788235" iyz="0.0" ixx="0.0026193100408363" iyy="0.0026193100408363" ixy="0.0" ixz="0.0" />
      <mass value="1.0" />
      </inertial>
    <collision name="ur3_link">
      <origin rpy="-0.000000 3.141593 -3.141593" xyz="0.000095 -0.000194 0.066355" />
      <geometry>
        <cylinder radius="0.03120630979538" length="0.032068222761154" />
        </geometry>
      </collision>
    <visual name="ur3_link7_visible">
      <origin rpy="1.570796 1.570796 0.000000" xyz="0.000095 -0.003602 0.066354" />
      <geometry>
        <mesh filename="UR3_link7_visible_vis_1.dae" />
        </geometry>
      <material name="ur3_link7_visible_material">
        <color rgba="0.870588 0.870588 0.870588 1.0" />
        </material>
      </visual>
    <visual name="ur3_link7_visible">
      <origin rpy="1.570796 1.570796 0.000000" xyz="0.000095 -0.003602 0.066354" />
      <geometry>
        <mesh filename="UR3_link7_visible_vis_2.dae" />
        </geometry>
      <material name="ur3_link7_visible_material">
        <color rgba="0.870588 0.870588 0.870588 1.0" />
        </material>
      </visual>
    </link>
  <joint name="husky_to_ur3_mount" type="fixed">
    <parent link="husky_top_plate_link" />
    <child link="ur3_robot_base" />
    <origin xyz="0 0 0.2" rpy="0 0 -3.14159265359" />
    </joint>
  <link name="wsg50_base_link">
    <inertial>
      <origin xyz="0.0 0.0 0.0" rpy="0.0 -0.0 0.0" />
      <mass value="1.2" />
      <inertia ixx="1.0" ixy="0.0" ixz="0.0" iyy="1.0" iyz="0.0" izz="1.0" />
      </inertial>
    <visual name="wsg50_base_link_visual">
      <origin xyz="0.0 0.0 0.0" rpy="0.0 -0.0 0.0" />
      <geometry>
        <mesh filename="meshes/WSG50_110.stl" scale="1 1 1" />
        </geometry>
      </visual>
    <collision name="wsg50_base_link_collision">
      <origin xyz="0.0 0.0 0.0" rpy="0.0 -0.0 0.0" />
      <geometry>
        <box size="0.2 0.05 0.05" />
        </geometry>
      </collision>
    </link>
  <link name="wsg50_gripper_left">
    <inertial>
      <origin xyz="0.0 0.0 0.0115" rpy="0.0 -0.0 0.0" />
      <mass value="0.2" />
      <inertia ixx="0.1" ixy="0.0" ixz="0.0" iyy="0.1" iyz="0.0" izz="0.1" />
      </inertial>
    <visual name="wsg50_gripper_left_visual">
      <origin xyz="0.0 0.0 0.0" rpy="0.0 -0.0 0.0" />
      <geometry>
        <mesh filename="meshes/GUIDE_WSG50_110.stl" scale="0.001 0.001 0.001" />
        </geometry>
      </visual>
    <visual name="wsg50_gripper_left_fixed_joint_lump__finger_left_visual_1">
      <origin xyz="0.0 0.0 0.023" rpy="0.0 -0.0 0.0" />
      <geometry>
        <mesh filename="meshes/WSG-FMF.stl" scale="0.001 0.001 0.001" />
        </geometry>
      </visual>
    <collision name="wsg50_gripper_left_collision">
      <origin xyz="0.0 0.0 0.0" rpy="0.0 -0.0 0.0" />
      <geometry>
        <mesh filename="meshes/GUIDE_WSG50_110.stl" scale="0.001 0.001 0.001" />
        </geometry>
      </collision>
    <collision name="wsg50_gripper_left_fixed_joint_lump__finger_left_collision_1">
      <origin xyz="0.0 0.0 0.023" rpy="0.0 -0.0 0.0" />
      <geometry>
        <mesh filename="meshes/WSG-FMF.stl" scale="0.001 0.001 0.001" />
        </geometry>
      </collision>
    </link>
  <link name="wsg50_gripper_right">
    <inertial>
      <origin xyz="0.0 0.0 0.0115" rpy="0.0 -0.0 0.0" />
      <mass value="0.2" />
      <inertia ixx="0.1" ixy="0.0" ixz="0.0" iyy="0.1" iyz="0.0" izz="0.1" />
      </inertial>
    <visual name="wsg50_gripper_right_visual">
      <origin xyz="0.0 0.0 0.0" rpy="0.0 -0.0 0.0" />
      <geometry>
        <mesh filename="meshes/GUIDE_WSG50_110.stl" scale="0.001 0.001 0.001" />
        </geometry>
      </visual>
    <visual name="wsg50_gripper_right_fixed_joint_lump__finger_right_visual_1">
      <origin xyz="0.0 0.0 0.023" rpy="0.0 -0.0 0.0" />
      <geometry>
        <mesh filename="meshes/WSG-FMF.stl" scale="0.001 0.001 0.001" />
        </geometry>
      </visual>
    <collision name="wsg50_gripper_right_collision">
      <origin xyz="0.0 0.0 0.0" rpy="0.0 -0.0 0.0" />
      <geometry>
        <mesh filename="meshes/GUIDE_WSG50_110.stl" scale="0.001 0.001 0.001" />
        </geometry>
      </collision>
    <collision name="wsg50_gripper_right_fixed_joint_lump__finger_right_collision_1">
      <origin xyz="0.0 0.0 0.023" rpy="0.0 -0.0 0.0" />
      <geometry>
        <mesh filename="meshes/WSG-FMF.stl" scale="0.001 0.001 0.001" />
        </geometry>
      </collision>
    </link>
  <link name="wsg50_finger_right">
    <inertial>
      <origin xyz="0 0 0" rpy="0 0 0" />
      <mass value="0.2" />
      <inertia ixx="0.1" ixy="0.0" ixz="0.0" iyy="0.1" iyz="0.0" izz="0.1" />
      </inertial>
    <visual name="wsg50_finger_right_visual">
      <origin xyz="0.0 0.0 0.0" rpy="0.0 0.0 0.0" />
      <geometry>
        <mesh filename="meshes/l_gripper_tip_scaled.stl" scale="1 1 1" />
        </geometry>
      </visual>
    <collision name="wsg50_finger_right_collision">
      <origin xyz="0.0 0.0 0.042" rpy="0.0 0.0 0.0" />
      <geometry>
        <box size="0.02 0.02 0.15" />
        </geometry>
      </collision>
    </link>
  <link name="wsg50_finger_left">
    <inertial>
      <origin xyz="0 0 0" rpy="0 0 0" />
      <mass value="0.2" />
      <inertia ixx="0.1" ixy="0.0" ixz="0.0" iyy="0.1" iyz="0.0" izz="0.1" />
      </inertial>
    <visual name="wsg50_finger_left_visual">
      <origin xyz="0.0 0.0 0.0" rpy="0.0 0.0 0.0" />
      <geometry>
        <mesh filename="meshes/l_gripper_tip_scaled.stl" scale="1 1 1" />
        </geometry>
      </visual>
    <collision name="wsg50_finger_left_collision">
      <origin xyz="0.0 0.0 0.042" rpy="0.0 0.0 0.0" />
      <geometry>
        <box size="0.02 0.02 0.15" />
        </geometry>
      </collision>
    </link>
  <joint name="ur3_to_wsg50_fixed" type="fixed">
    <parent link="ur3_link_6" />
    <child link="wsg50_base_link" />
    <origin xyz="0.0 0.0 0.1" rpy="3.14159 3.14159 0.00000" />
    </joint>
  <joint name="wsg50_base_joint_gripper_left" type="prismatic">
    <parent link="wsg50_base_link" />
    <child link="wsg50_gripper_left" />
    <origin xyz="-0.055 0.0 0.0" rpy="0.0 -0.0 0.0" />
    <axis xyz="1 0 0" />
    <limit lower="-0.001" upper="0.055" effort="1" velocity="1" />
    </joint>
  <joint name="wsg50_base_joint_gripper_right" type="prismatic">
    <parent link="wsg50_base_link" />
    <child link="wsg50_gripper_right" />
    <origin xyz="0.055 0.0 0.0" rpy="0.0 -0.0 3.14159" />
    <axis xyz="-1 0 0" />
    <limit lower="-0.055" upper="0.001" effort="1" velocity="1" />
    </joint>
  <joint name="wsg50_gripper_finger_right" type="fixed">
    <parent link="wsg50_gripper_right" />
    <child link="wsg50_finger_right" />
    <origin xyz="-0.006999999999975352 -1.857512855346907e-08 0.145" rpy="0.0 -0.0 -1.57079" />
    </joint>
  <joint name="wsg50_gripper_finger_left" type="fixed">
    <parent link="wsg50_gripper_left" />
    <child link="wsg50_finger_left" />
    <origin xyz="-0.006999999999999999 0.0 0.145" rpy="0.0 -0.0 -1.5707953071795864" />
    </joint>
  </robot>